The following modules were not unloaded:
  (Use "module --force purge" to unload all):

  1) 2023.01   2) StdEnv

The following have been reloaded with a version change:
  1) GCCcore/13.2.0 => GCCcore/11.3.0
  2) XZ/5.4.4-GCCcore-13.2.0 => XZ/5.2.5-GCCcore-11.3.0
  3) binutils/2.40-GCCcore-13.2.0 => binutils/2.38-GCCcore-11.3.0
  4) bzip2/1.0.8-GCCcore-13.2.0 => bzip2/1.0.8-GCCcore-11.3.0
  5) zlib/1.2.13-GCCcore-13.2.0 => zlib/1.2.12-GCCcore-11.3.0

Generating train split: 0 examples [00:00, ? examples/s]Generating train split: 6267 examples [00:00, 140011.95 examples/s]
Generating validation split: 0 examples [00:00, ? examples/s]Generating validation split: 783 examples [00:00, 78684.65 examples/s]
Generating test split: 0 examples [00:00, ? examples/s]Generating test split: 784 examples [00:00, 74217.04 examples/s]
`torch_dtype` is deprecated! Use `dtype` instead!
Fetching 19 files:   0%|          | 0/19 [00:00<?, ?it/s]/home5/s5542332/venvs/first_env/lib/python3.11/site-packages/huggingface_hub/file_download.py:798: UserWarning: Not enough free disk space to download the file. The expected file size is: 4899.04 MB. The target location /home5/s5542332/.cache/huggingface/hub/models--mistralai--Mixtral-8x7B-Instruct-v0.1/blobs only has 3967.81 MB free disk space.
  warnings.warn(
/home5/s5542332/venvs/first_env/lib/python3.11/site-packages/huggingface_hub/file_download.py:798: UserWarning: Not enough free disk space to download the file. The expected file size is: 4892.81 MB. The target location /home5/s5542332/.cache/huggingface/hub/models--mistralai--Mixtral-8x7B-Instruct-v0.1/blobs only has 3967.81 MB free disk space.
  warnings.warn(
/home5/s5542332/venvs/first_env/lib/python3.11/site-packages/huggingface_hub/file_download.py:798: UserWarning: Not enough free disk space to download the file. The expected file size is: 4983.00 MB. The target location /home5/s5542332/.cache/huggingface/hub/models--mistralai--Mixtral-8x7B-Instruct-v0.1/blobs only has 3967.81 MB free disk space.
  warnings.warn(
/home5/s5542332/venvs/first_env/lib/python3.11/site-packages/huggingface_hub/file_download.py:798: UserWarning: Not enough free disk space to download the file. The expected file size is: 4983.00 MB. The target location /home5/s5542332/.cache/huggingface/hub/models--mistralai--Mixtral-8x7B-Instruct-v0.1/blobs only has 1.05 MB free disk space.
  warnings.warn(
/home5/s5542332/venvs/first_env/lib/python3.11/site-packages/huggingface_hub/file_download.py:798: UserWarning: Not enough free disk space to download the file. The expected file size is: 4899.04 MB. The target location /home5/s5542332/.cache/huggingface/hub/models--mistralai--Mixtral-8x7B-Instruct-v0.1/blobs only has 1.05 MB free disk space.
  warnings.warn(
Fetching 19 files:   0%|          | 0/19 [00:14<?, ?it/s]
Traceback (most recent call last):
  File "/home5/s5542332/venvs/first_env/lib/python3.11/site-packages/huggingface_hub/file_download.py", line 1720, in _download_to_tmp_and_move
    xet_get(
  File "/home5/s5542332/venvs/first_env/lib/python3.11/site-packages/huggingface_hub/file_download.py", line 626, in xet_get
    download_files(
RuntimeError: Data processing error: CAS service error : IO Error: No space left on device (os error 28)

During handling of the above exception, another exception occurred:

Traceback (most recent call last):
  File "/scratch/s5542332/XED_group9/src/train_lora_llm.py", line 91, in <module>
    model = AutoModelForCausalLM.from_pretrained(
            ^^^^^^^^^^^^^^^^^^^^^^^^^^^^^^^^^^^^^
  File "/home5/s5542332/venvs/first_env/lib/python3.11/site-packages/transformers/models/auto/auto_factory.py", line 604, in from_pretrained
    return model_class.from_pretrained(
           ^^^^^^^^^^^^^^^^^^^^^^^^^^^^
  File "/home5/s5542332/venvs/first_env/lib/python3.11/site-packages/transformers/modeling_utils.py", line 277, in _wrapper
    return func(*args, **kwargs)
           ^^^^^^^^^^^^^^^^^^^^^
  File "/home5/s5542332/venvs/first_env/lib/python3.11/site-packages/transformers/modeling_utils.py", line 4900, in from_pretrained
    checkpoint_files, sharded_metadata = _get_resolved_checkpoint_files(
                                         ^^^^^^^^^^^^^^^^^^^^^^^^^^^^^^^
  File "/home5/s5542332/venvs/first_env/lib/python3.11/site-packages/transformers/modeling_utils.py", line 1200, in _get_resolved_checkpoint_files
    checkpoint_files, sharded_metadata = get_checkpoint_shard_files(
                                         ^^^^^^^^^^^^^^^^^^^^^^^^^^^
  File "/home5/s5542332/venvs/first_env/lib/python3.11/site-packages/transformers/utils/hub.py", line 1084, in get_checkpoint_shard_files
    cached_filenames = cached_files(
                       ^^^^^^^^^^^^^
  File "/home5/s5542332/venvs/first_env/lib/python3.11/site-packages/transformers/utils/hub.py", line 567, in cached_files
    raise e
  File "/home5/s5542332/venvs/first_env/lib/python3.11/site-packages/transformers/utils/hub.py", line 494, in cached_files
    snapshot_download(
  File "/home5/s5542332/venvs/first_env/lib/python3.11/site-packages/huggingface_hub/utils/_validators.py", line 114, in _inner_fn
    return fn(*args, **kwargs)
           ^^^^^^^^^^^^^^^^^^^
  File "/home5/s5542332/venvs/first_env/lib/python3.11/site-packages/huggingface_hub/_snapshot_download.py", line 332, in snapshot_download
    thread_map(
  File "/home5/s5542332/venvs/first_env/lib/python3.11/site-packages/tqdm/contrib/concurrent.py", line 69, in thread_map
    return _executor_map(ThreadPoolExecutor, fn, *iterables, **tqdm_kwargs)
           ^^^^^^^^^^^^^^^^^^^^^^^^^^^^^^^^^^^^^^^^^^^^^^^^^^^^^^^^^^^^^^^^
  File "/home5/s5542332/venvs/first_env/lib/python3.11/site-packages/tqdm/contrib/concurrent.py", line 51, in _executor_map
    return list(tqdm_class(ex.map(fn, *iterables, chunksize=chunksize), **kwargs))
           ^^^^^^^^^^^^^^^^^^^^^^^^^^^^^^^^^^^^^^^^^^^^^^^^^^^^^^^^^^^^^^^^^^^^^^^
  File "/home5/s5542332/venvs/first_env/lib/python3.11/site-packages/tqdm/std.py", line 1181, in __iter__
    for obj in iterable:
  File "/cvmfs/hpc.rug.nl/versions/2023.01/rocky8/x86_64/amd/zen3/software/Python/3.11.5-GCCcore-13.2.0/lib/python3.11/concurrent/futures/_base.py", line 619, in result_iterator
    yield _result_or_cancel(fs.pop())
          ^^^^^^^^^^^^^^^^^^^^^^^^^^^
  File "/cvmfs/hpc.rug.nl/versions/2023.01/rocky8/x86_64/amd/zen3/software/Python/3.11.5-GCCcore-13.2.0/lib/python3.11/concurrent/futures/_base.py", line 317, in _result_or_cancel
    return fut.result(timeout)
           ^^^^^^^^^^^^^^^^^^^
  File "/cvmfs/hpc.rug.nl/versions/2023.01/rocky8/x86_64/amd/zen3/software/Python/3.11.5-GCCcore-13.2.0/lib/python3.11/concurrent/futures/_base.py", line 456, in result
    return self.__get_result()
           ^^^^^^^^^^^^^^^^^^^
  File "/cvmfs/hpc.rug.nl/versions/2023.01/rocky8/x86_64/amd/zen3/software/Python/3.11.5-GCCcore-13.2.0/lib/python3.11/concurrent/futures/_base.py", line 401, in __get_result
    raise self._exception
  File "/cvmfs/hpc.rug.nl/versions/2023.01/rocky8/x86_64/amd/zen3/software/Python/3.11.5-GCCcore-13.2.0/lib/python3.11/concurrent/futures/thread.py", line 58, in run
    result = self.fn(*self.args, **self.kwargs)
             ^^^^^^^^^^^^^^^^^^^^^^^^^^^^^^^^^^
  File "/home5/s5542332/venvs/first_env/lib/python3.11/site-packages/huggingface_hub/_snapshot_download.py", line 306, in _inner_hf_hub_download
    return hf_hub_download(
           ^^^^^^^^^^^^^^^^
  File "/home5/s5542332/venvs/first_env/lib/python3.11/site-packages/huggingface_hub/utils/_validators.py", line 114, in _inner_fn
    return fn(*args, **kwargs)
           ^^^^^^^^^^^^^^^^^^^
  File "/home5/s5542332/venvs/first_env/lib/python3.11/site-packages/huggingface_hub/file_download.py", line 1007, in hf_hub_download
    return _hf_hub_download_to_cache_dir(
           ^^^^^^^^^^^^^^^^^^^^^^^^^^^^^^
  File "/home5/s5542332/venvs/first_env/lib/python3.11/site-packages/huggingface_hub/file_download.py", line 1168, in _hf_hub_download_to_cache_dir
    _download_to_tmp_and_move(
  File "/home5/s5542332/venvs/first_env/lib/python3.11/site-packages/huggingface_hub/file_download.py", line 1706, in _download_to_tmp_and_move
    with incomplete_path.open("ab") as f:
OSError: [Errno 28] No space left on device
